Successful exception
CallStack (from HasCallStack):
  error, called at t13330.hs:5:16 in main:Main
